Workbook

Sheet Data
A1: Full Name | B1: Title | C1: Mentor | D1: Field | E1: First Pron | F1: Last Pron | G1: Email | H1: Kerb
A2: Aaryan Patel | B2: TailSeeker: Optimizing Molecular Structure Generation for Fibrodysplasia Ossificans Progressiva | C2: Prof. Gil Alterovitz | D2: Computer Science & AI | E2: AR-ee-un | F2: puh-TELL | G2: aaru0302@mit.edu | H2: aaru0302
A3: Abigail Qi | B3: Optimization of a Yeast-Based High-Throughput Screening Platform to Detect Small-Molecule Modulators of PfPDE𝛄 for Antimalarial Drug Discovery | C3: Prof. Charles Hoffman | D3: Biology & Medicine | E3: Abigail | F3: CHEE | G3: abihqi@mit.edu | H3: abihqi
A4: Ahmed Sultan | B4: Mapping Myo-15 Cre Activity in Cochleae to Validate Disease Models for​ Usher Syndrome Type 1F Gene Therapy | C4: Dr. Artur A. Indzhykulian | D4: Biology & Medicine | E4: AH-med | F4: SUL-tun | G4: a_sultan@mit.edu | H4: a_sultan
A5: Alejandra Stephanie Perry | B5: Critical Windows for Neuromodulatory Recovery: Reversible UNC-31 Depletion in Caenorhabditis elegans Development | C5: Prof. Vivek Venkatachalam | D5: Biology & Medicine | E5: ah-leh-HAHN-dra STEH-fah-NEE | F5: PAIR-ee | G5: asperry@mit.edu | H5: asperry
A6: Alejandro Mayorga | B6: Liquid Foundation Models as Medical Assistants | C6: Dr. Bo Wu | D6: Computer Science & AI | E6: ah-leh-HAHN-dro | F6: my-OR-ga | G6: alej0@mit.edu | H6: alej0
A7: Alex Ren | B7: Using Cell-Projected Phenotypes to study HIV induced cognitive decline | C7: Prof. Manolis Kellis | D7: Biology & Medicine | E7: AL-ex | F7: REN | G7: alexren@mit.edu | H7: alexren
A8: Alexis Cho | B8: Interactions of lipid droplets and Them1-containing condensates to regulate metabolism | C8: Prof. Susan Hagen, Dr. Xu Xu | D8: Biology & Medicine | E8: ah-LEX-is | F8: CHOH | G8: alexicho@mit.edu | H8: alexicho
A9: Amogh Dattatri | B9: Dissecting the effects of non-coding genetic variation on neuropsychiatric disorder susceptibility | C9: Prof. Manolis Kellis | D9: Biology & Medicine | E9: ah-MOHG | F9: DAH-tah-tree | G9: amogh28@mit.edu | H9: amogh28
A10: Amritha Praveen | B10: Analyzing the Correlation of SBayesRC Calculated Weights for Polygenic Risk Scores and Body Mass Index | C10: Dr. Buu Truong | D10: Biology & Medicine | E10: um-REE-tha | F10: pra-VEEN | G10: amritha9@mit.edu | H10: amritha9
A11: Andy Jo | B11: Affine-Normalized Geometry of Protein Ensembles | C11: Prof. Gil Alterovitz | D11: Biology & Medicine | E11: AN-dee | F11: JOH | G11: minkyujo@mit.edu | H11: minkyujo
A12: Annika Chadha | B12: Reproducing the Energy Landscape of Nanoparticle-Induced Lipid Membrane Deformation | C12: Prof. Maggie Qi, Shu Yang | D12: Chemistry & Materials | E12: AH-nih-kah | F12: CHAH-dah | G12: annika8@mit.edu | H12: annika8
... A101: Álvaro Daniel Villafuerte González | B101: Towards Scaling Laws For Long-Horizon Software Engineering Agents | C101: Prof. Manolis Kellis | D101: Computer Science & AI | E101: AHL-vah-ro Daniel | F101: vee-ya-FWER-teh gon-SAH-les | G101: advg@mit.edu | H101: advg

Sheet Schedule
A1: RSI 2026 Symposium Schedule
A2: Edit a Name cell to reassign a slot -- Field / Title / Mentor update automatically.
A5: Thursday, August 6, 2026
A6: Block T1 (9:00 AM – 10:30 AM)
A7: Time | B7: Room 32-124 | F7: Room 32-141 | J7: Room 32-155
B8: Name | C8: Field | D8: Title | E8: Mentor | F8: Name | G8: Field | H8: Title | I8: Mentor | J8: Name | K8: Field | L8: Title | M8: Mentor
A9: 9:00 AM – 9:15 AM | B9: Mira Cakmak | C9: =IFERROR(VLOOKUP($B9,Data!$A:$D,4,FALSE),"") -> Neuroscience & Psychology | D9: =IFERROR(VLOOKUP($B9,Data!$A:$D,2,FALSE),"") -> Visualizing Neuropsychological Profiles in Patients with Alzheimer's Disease | E9: =IFERROR(VLOOKUP($B9,Data!$A:$D,3,FALSE),"") -> Dr. Daniel Press and Dr. Hsueh-Sheng Chiang | F9: Mahi Kohli | G9: =IFERROR(VLOOKUP($F9,Data!$A:$D,4,FALSE),"") -> Biology & Medicine | H9: =IFERROR(VLOOKUP($F9,Data!$A:$D,2,FALSE),"") -> Worming Our Way Out: Analyzing How Developmental Exposure to UNC-31 Degradation and TIR1 affect brain dynamics of C. elegans | I9: =IFERROR(VLOOKUP($F9,Data!$A:$D,3,FALSE),"") -> Prof. Vivek Venkatachalam | J9: Anushka Tonapi | K9: =IFERROR(VLOOKUP($J9,Data!$A:$D,4,FALSE),"") -> Math | L9: =IFERROR(VLOOKUP($J9,Data!$A:$D,2,FALSE),"") -> Counting Prime Solutions to Quadratic Forms | M9: =IFERROR(VLOOKUP($J9,Data!$A:$D,3,FALSE),"") -> Siqi Wu
A10: 9:15 AM – 9:30 AM | B10: Zephyr Larson | C10: =IFERROR(VLOOKUP($B10,Data!$A:$D,4,FALSE),"") -> Earth, Ocean & Climate | D10: =IFERROR(VLOOKUP($B10,Data!$A:$D,2,FALSE),"") -> Understanding the Role of Radiative Feedbacks and Forcings in the Land-Sea Warming Contrast | E10: =IFERROR(VLOOKUP($B10,Data!$A:$D,3,FALSE),"") -> Prof. Paul O'Gorman | F10: Alejandra Stephanie Perry | G10: =IFERROR(VLOOKUP($F10,Data!$A:$D,4,FALSE),"") -> Biology & Medicine | H10: =IFERROR(VLOOKUP($F10,Data!$A:$D,2,FALSE),"") -> Critical Windows for Neuromodulatory Recovery: Reversible UNC-31 Depletion in Caenorhabditis elegans Development | I10: =IFERROR(VLOOKUP($F10,Data!$A:$D,3,FALSE),"") -> Prof. Vivek Venkatachalam | J10: Grisham Paimagam | K10: =IFERROR(VLOOKUP($J10,Data!$A:$D,4,FALSE),"") -> Math | L10: =IFERROR(VLOOKUP($J10,Data!$A:$D,2,FALSE),"") -> Sphere Packing on Grassmannians | M10: =IFERROR(VLOOKUP($J10,Data!$A:$D,3,FALSE),"") -> Siqi Wu
A11: 9:30 AM – 9:45 AM | B11: Alejandro Mayorga | C11: =IFERROR(VLOOKUP($B11,Data!$A:$D,4,FALSE),"") -> Computer Science & AI | D11: =IFERROR(VLOOKUP($B11,Data!$A:$D,2,FALSE),"") -> Liquid Foundation Models as Medical Assistants | E11: =IFERROR(VLOOKUP($B11,Data!$A:$D,3,FALSE),"") -> Dr. Bo Wu | F11: Ferris Li | G11: =IFERROR(VLOOKUP($F11,Data!$A:$D,4,FALSE),"") -> Computer Science & AI | H11: =IFERROR(VLOOKUP($F11,Data!$A:$D,2,FALSE),"") -> Building a Machine Learning Model to Resolve C. elegans Collisions | I11: =IFERROR(VLOOKUP($F11,Data!$A:$D,3,FALSE),"") -> Prof. Vivek Venkatachalam | J11: Sirius Sun | K11: =IFERROR(VLOOKUP($J11,Data!$A:$D,4,FALSE),"") -> Math | L11: =IFERROR(VLOOKUP($J11,Data!$A:$D,2,FALSE),"") -> Critical Groups of Signed Subdivided Wheels | M11: =IFERROR(VLOOKUP($J11,Data!$A:$D,3,FALSE),"") -> Ryota Inagaki
A12: 9:45 AM – 10:00 AM | B12: Eric Buehler | C12: =IFERROR(VLOOKUP($B12,Data!$A:$D,4,FALSE),"") -> Computer Science & AI | D12: =IFERROR(VLOOKUP($B12,Data!$A:$D,2,FALSE),"") -> Two-Stage Outcome-Based Reinforcement Learning for a Compact Medical Vision-Language Model | E12: =IFERROR(VLOOKUP($B12,Data!$A:$D,3,FALSE),"") -> Dr. Bo Wu | F12: Benson Hsueh | G12: =IFERROR(VLOOKUP($F12,Data!$A:$D,4,FALSE),"") -> Computer Science & AI | H12: =IFERROR(VLOOKUP($F12,Data!$A:$D,2,FALSE),"") -> The Center Configuration Problem for Single-Robot Reconfiguration | I12: =IFERROR(VLOOKUP($F12,Data!$A:$D,3,FALSE),"") -> Timothy Gomez | J12: Michael Luo | K12: =IFERROR(VLOOKUP($J12,Data!$A:$D,4,FALSE),"") -> Math | L12: =IFERROR(VLOOKUP($J12,Data!$A:$D,2,FALSE),"") -> Resolving a Conjecture on Stack-Sorting | M12: =IFERROR(VLOOKUP($J12,Data!$A:$D,3,FALSE),"") -> Ryota Inagaki
A13: 10:00 AM – 10:15 AM | B13: Layth Alzahrani | C13: =IFERROR(VLOOKUP($B13,Data!$A:$D,4,FALSE),"") -> Computer Science & AI | D13: =IFERROR(VLOOKUP($B13,Data!$A:$D,2,FALSE),"") -> Crown–Root Segmentation in Dental CBCT Using Anatomically Guided Synthetic Annotation | E13: =IFERROR(VLOOKUP($B13,Data!$A:$D,3,FALSE),"") -> Dr. Bo Wu | F13: Matey Minev | G13: =IFERROR(VLOOKUP($F13,Data!$A:$D,4,FALSE),"") -> Computer Science & AI | H13: =IFERROR(VLOOKUP($F13,Data!$A:$D,2,FALSE),"") -> Before the Final Assembly: Temporal Leakage and Process Privacy in Covert Tile Automata | I13: =IFERROR(VLOOKUP($F13,Data!$A:$D,3,FALSE),"") -> Timothy Gomez | J13: Tony Lu | K13: =IFERROR(VLOOKUP($J13,Data!$A:$D,4,FALSE),"") -> Math | L13: =IFERROR(VLOOKUP($J13,Data!$A:$D,2,FALSE),"") -> Asymptotics for Curve Shortening Flow with Boundary | M13: =IFERROR(VLOOKUP($J13,Data!$A:$D,3,FALSE),"") -> Alexander McWeeney
A14: 10:15 AM – 10:30 AM | B14: Kai Xuen Toh | C14: =IFERROR(VLOOKUP($B14,Data!$A:$D,4,FALSE),"") -> Astronomy & Planetary Science | D14: =IFERROR(VLOOKUP($B14,Data!$A:$D,2,FALSE),"") -> Detecting Life in the Clouds: The Feasibility of Using UV Phase Delay Sensing on Venus | E14: =IFERROR(VLOOKUP($B14,Data!$A:$D,3,FALSE),"") -> Prof. Sara Seager | F14: Siddhi Kochar | G14: =IFERROR(VLOOKUP($F14,Data!$A:$D,4,FALSE),"") -> Astronomy & Planetary Science | H14: =IFERROR(VLOOKUP($F14,Data!$A:$D,2,FALSE),"") -> Constraints on Cosmic Reionization and the Thomson Optical Depth via the Population III.1 Flash Model | I14: =IFERROR(VLOOKUP($F14,Data!$A:$D,3,FALSE),"") -> Dr. James Sullivan | J14: Lincoln Liu | K14: =IFERROR(VLOOKUP($J14,Data!$A:$D,4,FALSE),"") -> Math | L14: =IFERROR(VLOOKUP($J14,Data!$A:$D,2,FALSE),"") -> Heat Evolution on Graphs | M14: =IFERROR(VLOOKUP($J14,Data!$A:$D,3,FALSE),"") -> Alexander McWeeney
A15: Break (10:30 AM – 11:00 AM)
A16: Block T2 (11:00 AM – 12:30 PM)
A17: Time | B17: Room 32-124 | F17: Room 32-141 | J17: Room 32-155
B18: Name | C18: Field | D18: Title | E18: Mentor | F18: Name | G18: Field | H18: Title | I18: Mentor | J18: Name | K18: Field | L18: Title | M18: Mentor
A19: 11:00 AM – 11:15 AM | B19: Eason Turner | C19: =IFERROR(VLOOKUP($B19,Data!$A:$D,4,FALSE),"") -> Astronomy & Planetary Science | D19: =IFERROR(VLOOKUP($B19,Data!$A:$D,2,FALSE),"") -> Searching for Eclipses in X-Ray Sources | E19: =IFERROR(VLOOKUP($B19,Data!$A:$D,3,FALSE),"") -> Dr. Rosanne Di Stefano | F19: Lluc Simon | G19: =IFERROR(VLOOKUP($F19,Data!$A:$D,4,FALSE),"") -> Physics | H19: =IFERROR(VLOOKUP($F19,Data!$A:$D,2,FALSE),"") -> Hybrid controls strategy for Automatic Laser Beam Alignment | I19: =IFERROR(VLOOKUP($F19,Data!$A:$D,3,FALSE),"") -> Prof. Vladan Vuletic | J19: Katrina Liu | K19: =IFERROR(VLOOKUP($J19,Data!$A:$D,4,FALSE),"") -> Math | L19: =IFERROR(VLOOKUP($J19,Data!$A:$D,2,FALSE),"") -> Temporal Preferential Attachment Trees | M19: =IFERROR(VLOOKUP($J19,Data!$A:$D,3,FALSE),"") -> Hang Du
A20: 11:15 AM – 11:30 AM | B20: Miguel Shim | C20: =IFERROR(VLOOKUP($B20,Data!$A:$D,4,FALSE),"") -> Physics | D20: =IFERROR(VLOOKUP($B20,Data!$A:$D,2,FALSE),"") -> Information Flow in Self Organizing Systems | E20: =IFERROR(VLOOKUP($B20,Data!$A:$D,3,FALSE),"") -> Ashu Tripathi | F20: Mikołaj Stefaniak | G20: =IFERROR(VLOOKUP($F20,Data!$A:$D,4,FALSE),"") -> Physics | H20: =IFERROR(VLOOKUP($F20,Data!$A:$D,2,FALSE),"") -> Optical pulse shaping for quantum-enhanced clocks | I20: =IFERROR(VLOOKUP($F20,Data!$A:$D,3,FALSE),"") -> Prof. Vladan Vuletic | J20: Nikola Veselinov | K20: =IFERROR(VLOOKUP($J20,Data!$A:$D,4,FALSE),"") -> Math | L20: =IFERROR(VLOOKUP($J20,Data!$A:$D,2,FALSE),"") -> On Supersingular Isogeny Graphs of Drinfeld Modules | M20: =IFERROR(VLOOKUP($J20,Data!$A:$D,3,FALSE),"") -> Ayan Nath
A21: 11:30 AM – 11:45 AM | B21: Sylvia Lee | C21: =IFERROR(VLOOKUP($B21,Data!$A:$D,4,FALSE),"") -> Physics | D21: =IFERROR(VLOOKUP($B21,Data!$A:$D,2,FALSE),"") -> Life is a Game: Learning Dynamical Systems with Neural Cellular Automata | E21: =IFERROR(VLOOKUP($B21,Data!$A:$D,3,FALSE),"") -> Ashu Tripathi | F21: Mustafa Bakhodirov | G21: =IFERROR(VLOOKUP($F21,Data!$A:$D,4,FALSE),"") -> Engineering | H21: =IFERROR(VLOOKUP($F21,Data!$A:$D,2,FALSE),"") -> Patient-Specific Modeling of Cerebrospinal Fluid Flow in Chiari I Malformation | I21: =IFERROR(VLOOKUP($F21,Data!$A:$D,3,FALSE),"") -> Prof. Francis Loth and Hannah Higgins | J21: Timothy Chen | K21: =IFERROR(VLOOKUP($J21,Data!$A:$D,4,FALSE),"") -> Math | L21: =IFERROR(VLOOKUP($J21,Data!$A:$D,2,FALSE),"") -> Open Cases of the Colmez Conjecture | M21: =IFERROR(VLOOKUP($J21,Data!$A:$D,3,FALSE),"") -> Ayan Nath
A22: 11:45 AM – 12:00 PM | B22: Pavan Subramani | C22: =IFERROR(VLOOKUP($B22,Data!$A:$D,4,FALSE),"") -> Chemistry & Materials | D22: =IFERROR(VLOOKUP($B22,Data!$A:$D,2,FALSE),"") -> The computational conversion of a singular apo structure to an ensemble of holo structures for more accurate molecular docking | E22: =IFERROR(VLOOKUP($B22,Data!$A:$D,3,FALSE),"") -> Dr. Mrinal Shekhar | F22: Asher Wang | G22: =IFERROR(VLOOKUP($F22,Data!$A:$D,4,FALSE),"") -> Biology & Medicine | H22: =IFERROR(VLOOKUP($F22,Data!$A:$D,2,FALSE),"") -> Temporal Mapping of Doxorubicin-Induced Alterations in Autophagic Flux in hiPSC-Derived Cardiomyocytes | I22: =IFERROR(VLOOKUP($F22,Data!$A:$D,3,FALSE),"") -> Dr. Howard Chen | J22: Jay Athipatla | K22: =IFERROR(VLOOKUP($J22,Data!$A:$D,4,FALSE),"") -> Math | L22: =IFERROR(VLOOKUP($J22,Data!$A:$D,2,FALSE),"") -> Effective Computation of Free Resolutions and Cohomology for Quotients of Braid Groups | M22: =IFERROR(VLOOKUP($J22,Data!$A:$D,3,FALSE),"") -> Dr. Sean Carroll
A23: 12:00 PM – 12:15 PM | B23: Cassidy Stocker | C23: =IFERROR(VLOOKUP($B23,Data!$A:$D,4,FALSE),"") -> Biology & Medicine | D23: =IFERROR(VLOOKUP($B23,Data!$A:$D,2,FALSE),"") -> Effect of ZAP70 Mutations on CAR T-Cell Effectiveness Targeting GD2 in Cancer Cells | E23: =IFERROR(VLOOKUP($B23,Data!$A:$D,3,FALSE),"") -> Dr. Robbie G. Majzner | F23: Rishi Pampati | G23: =IFERROR(VLOOKUP($F23,Data!$A:$D,4,FALSE),"") -> Neuroscience & Psychology | H23: =IFERROR(VLOOKUP($F23,Data!$A:$D,2,FALSE),"") -> Functional Neural Connectivity During Inactivation of the Anterior Insula in Fentanyl-Administered Rats | I23: =IFERROR(VLOOKUP($F23,Data!$A:$D,3,FALSE),"") -> Dr. Sarah Bricault | J23: Leyu Girma | K23: =IFERROR(VLOOKUP($J23,Data!$A:$D,4,FALSE),"") -> Math | L23: =IFERROR(VLOOKUP($J23,Data!$A:$D,2,FALSE),"") -> Resolutions for Quotients of One-Relator Groups | M23: =IFERROR(VLOOKUP($J23,Data!$A:$D,3,FALSE),"") -> Dr. Sean Carroll
A24: 12:15 PM – 12:30 PM | B24: Sara Mitchell | C24: =IFERROR(VLOOKUP($B24,Data!$A:$D,4,FALSE),"") -> Biology & Medicine | D24: =IFERROR(VLOOKUP($B24,Data!$A:$D,2,FALSE),"") -> Identifying Alternative Stimulatory Receptors for TCR-independent Activation of T-cells | E24: =IFERROR(VLOOKUP($B24,Data!$A:$D,3,FALSE),"") -> Dr. Robbie G. Majzner | F24: Shaden Alharbi | G24: =IFERROR(VLOOKUP($F24,Data!$A:$D,4,FALSE),"") -> Biology & Medicine | H24: =IFERROR(VLOOKUP($F24,Data!$A:$D,2,FALSE),"") -> Characterization of Nanobody Binding to HIV-1 Capsid-Like Particles via Biolayer Interferometry | I24: =IFERROR(VLOOKUP($F24,Data!$A:$D,3,FALSE),"") -> Dr. Ky Lowenhaupt | J24: Riya Mehrotra | K24: =IFERROR(VLOOKUP($J24,Data!$A:$D,4,FALSE),"") -> Math | L24: =IFERROR(VLOOKUP($J24,Data!$A:$D,2,FALSE),"") -> Simplified Volume Formulas for Tetrahedron by Edge-length Symmetry Class | M24: =IFERROR(VLOOKUP($J24,Data!$A:$D,3,FALSE),"") -> Prof. Eric Grinberg
A25: Lunch Break (12:30 PM – 1:15 PM)
A26: Block T3 (1:15 PM – 2:45 PM)
A27: Time | B27: Room 32-124 | F27: Room 32-141 | J27: Room 32-155
B28: Name | C28: Field | D28: Title | E28: Mentor | F28: Name | G28: Field | H28: Title | I28: Mentor | J28: Name | K28: Field | L28: Title | M28: Mentor
A29: 1:15 PM – 1:30 PM | B29: Atharva Tyagi | C29: =IFERROR(VLOOKUP($B29,Data!$A:$D,4,FALSE),"") -> Earth, Ocean & Climate | D29: =IFERROR(VLOOKUP($B29,Data!$A:$D,2,FALSE),"") -> Navier–Stokes Characteristic Boundary Conditions for Limited-Area Numerical Weather Prediction | E29: =IFERROR(VLOOKUP($B29,Data!$A:$D,3,FALSE),"") -> Prof. Pierre F.J Lermusiaux | F29: Shrivali Gupta | G29: =IFERROR(VLOOKUP($F29,Data!$A:$D,4,FALSE),"") -> Neuroscience & Psychology | H29: =IFERROR(VLOOKUP($F29,Data!$A:$D,2,FALSE),"") -> Examining the Relationship Between Executive Function and Behavioural Outcomes in Children | I29: =IFERROR(VLOOKUP($F29,Data!$A:$D,3,FALSE),"") -> Prof. John D. E. Gabrieli | J29: Tara Saini | K29: =IFERROR(VLOOKUP($J29,Data!$A:$D,4,FALSE),"") -> Math | L29: =IFERROR(VLOOKUP($J29,Data!$A:$D,2,FALSE),"") -> Enumerating Nilpotent Matrices over Finite Fields | M29: =IFERROR(VLOOKUP($J29,Data!$A:$D,3,FALSE),"") -> Prof. Eric Grinberg
A30: 1:30 PM – 1:45 PM | B30: Ayush Vispute | C30: =IFERROR(VLOOKUP($B30,Data!$A:$D,4,FALSE),"") -> Earth, Ocean & Climate | D30: =IFERROR(VLOOKUP($B30,Data!$A:$D,2,FALSE),"") -> Optimizing Quasi Geostrophic Flow Solving An Embedded Neural Network | E30: =IFERROR(VLOOKUP($B30,Data!$A:$D,3,FALSE),"") -> Prof. Pierre F.J Lermusiaux | F30: Danu Kim | G30: =IFERROR(VLOOKUP($F30,Data!$A:$D,4,FALSE),"") -> Computer Science & AI | H30: =IFERROR(VLOOKUP($F30,Data!$A:$D,2,FALSE),"") -> The Feedback Horizon: When Physical Foreknowledge Becomes Decisive in Robotic Manipulation | I30: =IFERROR(VLOOKUP($F30,Data!$A:$D,3,FALSE),"") -> Prof. Chuchu Fan | J30: Xindi Luo | K30: =IFERROR(VLOOKUP($J30,Data!$A:$D,4,FALSE),"") -> Math | L30: =IFERROR(VLOOKUP($J30,Data!$A:$D,2,FALSE),"") -> A Taxicab Journey to Triangle Centres | M30: =IFERROR(VLOOKUP($J30,Data!$A:$D,3,FALSE),"") -> Prof. Eric Grinberg
A31: 1:45 PM – 2:00 PM | B31: Bryan Cho | C31: =IFERROR(VLOOKUP($B31,Data!$A:$D,4,FALSE),"") -> Earth, Ocean & Climate | D31: =IFERROR(VLOOKUP($B31,Data!$A:$D,2,FALSE),"") -> Parametric Study of Regime Transition in Quasi-Geostrophic Turbulence | E31: =IFERROR(VLOOKUP($B31,Data!$A:$D,3,FALSE),"") -> Prof. Pierre F.J Lermusiaux | F31: Leonardo Bartoccini | G31: =IFERROR(VLOOKUP($F31,Data!$A:$D,4,FALSE),"") -> Computer Science & AI | H31: =IFERROR(VLOOKUP($F31,Data!$A:$D,2,FALSE),"") -> Learning Reciprocity: Value-Based Intrinsic Rewards for Cooperation in Sequential Social Dilemmas | I31: =IFERROR(VLOOKUP($F31,Data!$A:$D,3,FALSE),"") -> Prof. Chuchu Fan | J31: Greeshma Vinoy | K31: =IFERROR(VLOOKUP($J31,Data!$A:$D,4,FALSE),"") -> Biology & Medicine | L31: =IFERROR(VLOOKUP($J31,Data!$A:$D,2,FALSE),"") -> APOE e4-Associated Microglial Transcriptional Signature Across Neurodegenerative Diseases | M31: =IFERROR(VLOOKUP($J31,Data!$A:$D,3,FALSE),"") -> Dr. Sudeshna Das
A32: 2:00 PM – 2:15 PM | B32: Claire Zhan | C32: =IFERROR(VLOOKUP($B32,Data!$A:$D,4,FALSE),"") -> Earth, Ocean & Climate | D32: =IFERROR(VLOOKUP($B32,Data!$A:$D,2,FALSE),"") -> Efficient Patching for Generative Super Resolution of Turbulent Flow Fields | E32: =IFERROR(VLOOKUP($B32,Data!$A:$D,3,FALSE),"") -> Prof. Pierre F.J Lermusiaux | F32: Namie Djaja | G32: =IFERROR(VLOOKUP($F32,Data!$A:$D,4,FALSE),"") -> Computer Science & AI | H32: =IFERROR(VLOOKUP($F32,Data!$A:$D,2,FALSE),"") -> A Teleoperation System as a Data Engine for Learning System Dynamics | I32: =IFERROR(VLOOKUP($F32,Data!$A:$D,3,FALSE),"") -> Prof. Chuchu Fan | J32: Sofia Passos | K32: =IFERROR(VLOOKUP($J32,Data!$A:$D,4,FALSE),"") -> Biology & Medicine | L32: =IFERROR(VLOOKUP($J32,Data!$A:$D,2,FALSE),"") -> Predicted glycolytic reprogramming in a microglial substate across neurodegenerative diseases. | M32: =IFERROR(VLOOKUP($J32,Data!$A:$D,3,FALSE),"") -> Dr. Sudeshna Das
A33: 2:15 PM – 2:30 PM | B33: Malin Janna Vega | C33: =IFERROR(VLOOKUP($B33,Data!$A:$D,4,FALSE),"") -> Earth, Ocean & Climate | D33: =IFERROR(VLOOKUP($B33,Data!$A:$D,2,FALSE),"") -> GPU-Accelerated Numerical Modeling of Idealized Ocean Circulation | E33: =IFERROR(VLOOKUP($B33,Data!$A:$D,3,FALSE),"") -> Prof. Pierre F.J Lermusiaux | F33: Rohan Peddamallu | G33: =IFERROR(VLOOKUP($F33,Data!$A:$D,4,FALSE),"") -> Computer Science & AI | H33: =IFERROR(VLOOKUP($F33,Data!$A:$D,2,FALSE),"") -> Neural CBF-based Safe RL for Robot Locomotion | I33: =IFERROR(VLOOKUP($F33,Data!$A:$D,3,FALSE),"") -> Prof. Chuchu Fan | J33: Can Nalbantoglu | K33: =IFERROR(VLOOKUP($J33,Data!$A:$D,4,FALSE),"") -> Computer Science & AI | L33: =IFERROR(VLOOKUP($J33,Data!$A:$D,2,FALSE),"") -> Sinkhorn Schrödinger Bridges for Graph Interpolations | M33: =IFERROR(VLOOKUP($J33,Data!$A:$D,3,FALSE),"") -> Prof. Justin Solomon
A34: 2:30 PM – 2:45 PM | B34: Yong Ding | C34: =IFERROR(VLOOKUP($B34,Data!$A:$D,4,FALSE),"") -> Earth, Ocean & Climate | D34: =IFERROR(VLOOKUP($B34,Data!$A:$D,2,FALSE),"") -> Quantifying the Information Availability of Spatial Observations for Ocean Flow Field Reconstruction with Diffusion Posterior Sampling | E34: =IFERROR(VLOOKUP($B34,Data!$A:$D,3,FALSE),"") -> Prof. Pierre F.J Lermusiaux | F34: Nabet El Hajjar | G34: =IFERROR(VLOOKUP($F34,Data!$A:$D,4,FALSE),"") -> Neuroscience & Psychology | H34: =IFERROR(VLOOKUP($F34,Data!$A:$D,2,FALSE),"") -> Neighborhood Disadvantage, White Matter Development, and Child Outcomes: Evidence from the ABCD Study | I34: =IFERROR(VLOOKUP($F34,Data!$A:$D,3,FALSE),"") -> Dr. Yogesh Rathi, Dr. Sinead Marie Kelly, Dr. Lipeng Ning | J34: Daniel Guo | K34: =IFERROR(VLOOKUP($J34,Data!$A:$D,4,FALSE),"") -> Engineering | L34: =IFERROR(VLOOKUP($J34,Data!$A:$D,2,FALSE),"") -> Low-Reynolds-Number Porous Bleed for Separation Control on Hypersonic Airplanes | M34: =IFERROR(VLOOKUP($J34,Data!$A:$D,3,FALSE),"") -> Prof. Wesley L. Harris
A35: Break (2:45 PM – 3:15 PM)
A36: Block T4 (3:15 PM – 4:45 PM)
A37: Time | B37: Room 32-124 | F37: Room 32-141 | J37: Room 32-155
B38: Name | C38: Field | D38: Title | E38: Mentor | F38: Name | G38: Field | H38: Title | I38: Mentor | J38: Name | K38: Field | L38: Title | M38: Mentor
A39: 3:15 PM – 3:30 PM | B39: Sophia Zhao | C39: =IFERROR(VLOOKUP($B39,Data!$A:$D,4,FALSE),"") -> Earth, Ocean & Climate | D39: =IFERROR(VLOOKUP($B39,Data!$A:$D,2,FALSE),"") -> Reachability-Based Path Planning Across Autonomous Ocean Vehicle Platforms | E39: =IFERROR(VLOOKUP($B39,Data!$A:$D,3,FALSE),"") -> Prof. Pierre F.J Lermusiaux | F39: Mahima Lele | G39: =IFERROR(VLOOKUP($F39,Data!$A:$D,4,FALSE),"") -> Economics & Policy | H39: =IFERROR(VLOOKUP($F39,Data!$A:$D,2,FALSE),"") -> Evaluating the FDA’s 510(k) Pathway for Approving AI/ML Medical Devices | I39: =IFERROR(VLOOKUP($F39,Data!$A:$D,3,FALSE),"") -> Prof. Timothy Miller | J39: Alex Ren | K39: =IFERROR(VLOOKUP($J39,Data!$A:$D,4,FALSE),"") -> Biology & Medicine | L39: =IFERROR(VLOOKUP($J39,Data!$A:$D,2,FALSE),"") -> Using Cell-Projected Phenotypes to study HIV induced cognitive decline | M39: =IFERROR(VLOOKUP($J39,Data!$A:$D,3,FALSE),"") -> Prof. Manolis Kellis
A40: 3:30 PM – 3:45 PM | B40: Sarah Dingli | C40: =IFERROR(VLOOKUP($B40,Data!$A:$D,4,FALSE),"") -> Biology & Medicine | D40: =IFERROR(VLOOKUP($B40,Data!$A:$D,2,FALSE),"") -> Computational and Mathematical Modeling of Cellular Dynamics in Hydrogels to Optimize Large-Scale Bioprinting | E40: =IFERROR(VLOOKUP($B40,Data!$A:$D,3,FALSE),"") -> Prof. Ron Weiss | F40: Cooper Ho | G40: =IFERROR(VLOOKUP($F40,Data!$A:$D,4,FALSE),"") -> Astronomy & Planetary Science | H40: =IFERROR(VLOOKUP($F40,Data!$A:$D,2,FALSE),"") -> Recovering Long-Transit Planet Signals in TESS Light Curves with Improved KeplerSpline Detrending | I40: =IFERROR(VLOOKUP($F40,Data!$A:$D,3,FALSE),"") -> Katharine Hesse | J40: Amogh Dattatri | K40: =IFERROR(VLOOKUP($J40,Data!$A:$D,4,FALSE),"") -> Biology & Medicine | L40: =IFERROR(VLOOKUP($J40,Data!$A:$D,2,FALSE),"") -> Dissecting the effects of non-coding genetic variation on neuropsychiatric disorder susceptibility | M40: =IFERROR(VLOOKUP($J40,Data!$A:$D,3,FALSE),"") -> Prof. Manolis Kellis
A41: 3:45 PM – 4:00 PM | B41: Dhruv Jain | C41: =IFERROR(VLOOKUP($B41,Data!$A:$D,4,FALSE),"") -> Physics | D41: =IFERROR(VLOOKUP($B41,Data!$A:$D,2,FALSE),"") -> Gyromagnetic Ratio and Protactinium Isotope-Shift Mapping for Electric Dipole Moment Searches | E41: =IFERROR(VLOOKUP($B41,Data!$A:$D,3,FALSE),"") -> Dr. Prajwal T. Mohan Murthy | F41: Lillie Lin Li | G41: =IFERROR(VLOOKUP($F41,Data!$A:$D,4,FALSE),"") -> Astronomy & Planetary Science | H41: =IFERROR(VLOOKUP($F41,Data!$A:$D,2,FALSE),"") -> Neptunian Ridge around faint stars | I41: =IFERROR(VLOOKUP($F41,Data!$A:$D,3,FALSE),"") -> Katharine Hesse | J41: Chloe Giglio | K41: =IFERROR(VLOOKUP($J41,Data!$A:$D,4,FALSE),"") -> Biology & Medicine | L41: =IFERROR(VLOOKUP($J41,Data!$A:$D,2,FALSE),"") -> Mapping the transcriptional and phenotypic heterogeneity of lung adenocarcinoma progression | M41: =IFERROR(VLOOKUP($J41,Data!$A:$D,3,FALSE),"") -> Prof. Manolis Kellis
A42: 4:00 PM – 4:15 PM | B42: Aaryan Patel | C42: =IFERROR(VLOOKUP($B42,Data!$A:$D,4,FALSE),"") -> Computer Science & AI | D42: =IFERROR(VLOOKUP($B42,Data!$A:$D,2,FALSE),"") -> TailSeeker: Optimizing Molecular Structure Generation for Fibrodysplasia Ossificans Progressiva | E42: =IFERROR(VLOOKUP($B42,Data!$A:$D,3,FALSE),"") -> Prof. Gil Alterovitz | F42: Lara Otico | G42: =IFERROR(VLOOKUP($F42,Data!$A:$D,4,FALSE),"") -> Biology & Medicine | H42: =IFERROR(VLOOKUP($F42,Data!$A:$D,2,FALSE),"") -> Evaluating the Efficacy of RAP-Mediated Steric Hinderance on LRP-1 to Inhibit TcdB Endocytosis and Limit C. difficile Pathogenesis | I42: =IFERROR(VLOOKUP($F42,Data!$A:$D,3,FALSE),"") -> Prof. Min Dong | J42: Ipek Zeynioğlu | K42: =IFERROR(VLOOKUP($J42,Data!$A:$D,4,FALSE),"") -> Chemistry & Materials | L42: =IFERROR(VLOOKUP($J42,Data!$A:$D,2,FALSE),"") -> Efficient Binding Free Energy Estimation through Conformational Sampling of Intermediate States | M42: =IFERROR(VLOOKUP($J42,Data!$A:$D,3,FALSE),"") -> Prof. Manolis Kellis
...
